# Generated by Django 4.2.3 on 2023-09-17 01:10

import datetime
from django.conf import settings
import django.core.validators
from django.db import migrations, models
import django.db.models.deletion
import django.utils.timezone


class Migration(migrations.Migration):

    dependencies = [
        migrations.swappable_dependency(settings.AUTH_USER_MODEL),
        ('core', '0006_likelog_gapt_likes'),
    ]

    operations = [
        migrations.AlterField(
            model_name='log',
            name='date',
            field=models.DateField(default=datetime.date.today, validators=[django.core.validators.MaxValueValidator(datetime.date(2023, 9, 17), message='You have entered a date that is beyond the current timeline. Please check your flux capacitor and try again.')]),
        ),
        migrations.CreateModel(
            name='ReGaptLog',
            fields=[
                ('id', models.BigAutoField(auto_created=True, primary_key=True, serialize=False, verbose_name='ID')),
                ('date', models.DateTimeField(default=django.utils.timezone.now)),
                ('gapt', models.ForeignKey(on_delete=django.db.models.deletion.CASCADE, to='core.gapt')),
                ('user', models.ForeignKey(on_delete=django.db.models.deletion.CASCADE, to=settings.AUTH_USER_MODEL)),
            ],
        ),
        migrations.AddField(
            model_name='gapt',
            name='reGapts',
            field=models.ManyToManyField(related_name='reGapts', through='core.ReGaptLog', to=settings.AUTH_USER_MODEL),
        ),
    ]
